<?xml version="1.0" ?>

<robot xmlns:xacro="http://www.ros.org/wiki/xacro">

  <xacro:macro name="wam_j5" params="parent">

	<link name="wam_link_5">
		<inertial>
			<mass value="0.12376019"/>
			<origin xyz="0.00008921 0.00511217 0.00435824" />
			<inertia ixx="0.00005587" ixy="0.00000026" ixz="0.00000000" iyy="0.00007817" iyz="-0.00000083" izz="0.00006594"/>
		</inertial>
		<visual>
			<origin rpy="0 0 0" xyz="0.0 0.0 0.0"/>
			<geometry name="wam_link_5_visual">
				<mesh filename="package://wam_description/meshes/wam5.stl" scale="1.0 1.0 1.0"/>
			</geometry>
			<material name="Grey">
				<color rgba="0.75 0.75 0.75 1.0"/>
			</material>
		</visual>
		<collision>
			<origin rpy="0 0 0" xyz="0.0 0.0 0.0"/>
			<geometry name="wam_link_5_collision">
				<mesh filename="package://wam_description/meshes/wam5.stl" scale="1.0 1.0 1.0"/>
			</geometry>
			<contact_coefficients kd="1.0" kp="1000.0" mu="0"/>
		</collision>
	</link>

	<gazebo reference="wam_link_5">
		<material>Gazebo/White</material>
		<selfCollide>true</selfCollide>
	</gazebo>

	<joint name="wam_joint_5" type="revolute">
		<parent link="${parent}"/>
		<child link="wam_link_5"/>
		<origin rpy="1.57079632679 0 0" xyz="-0.045 -0.3 0.0"/>
		<axis xyz="0 0 1"/>
		<limit effort="30" lower="-4.8" upper="1.3" velocity="2.0"/>
		<!-- <joint_properties damping="100.0" friction="1000.0" /> -->
		<dynamics damping="0.25" friction="${3.0/7}"/>
	</joint>

	<transmission name="j5_transmission">
		<type>transmission_interface/SimpleTransmission"</type>
		<joint name="wam_joint_5">
			<hardwareInterface>EffortJointInterface</hardwareInterface>
		</joint>
		<actuator name="j5_motor">
			<hardwareInterface>EffortJointInterface</hardwareInterface>
			<mechanicalReduction>1</mechanicalReduction>
		</actuator>
	</transmission>

  </xacro:macro>

</robot>

