<?xml version="1.0" ?>

<robot xmlns:xacro="http://www.ros.org/wiki/xacro">

  <xacro:macro name="wam_j4" params="parent">

	<link name="wam_link_4">
		<inertial>
			<mass value="1.06513649"/>
			<origin xyz="-0.043013 -0.15029 -1.52e-4" />
			<inertia ixx="6.171403900396302E-3" ixy="-3.253853817720842E-4" ixz="3.823497031140259E-7" iyy="1.1938572764041708E-3" iyz="-8.791854551099702E-6" izz="6.2223804817341365E-3"/>
		</inertial>
		<visual>
			<origin rpy="0 0 0" xyz="0.0 0.0 0.0"/>
			<geometry name="wam_link_4_visual">
				<mesh filename="package://wam_description/meshes/wam4.stl" scale="1.0 1.0 1.0"/>
			</geometry>
			<material name="Grey">
				<color rgba="0.75 0.75 0.75 1.0"/>
			</material>
		</visual>
		<collision>
			<origin rpy="0 0 0" xyz="0.0 0.0 0.0"/>
			<geometry name="wam_link_4_collision">
				<mesh filename="package://wam_description/meshes/wam4.stl" scale="1.0 1.0 1.0"/>
			</geometry>
		<contact_coefficients kd="1.0" kp="1000.0" mu="0"/>
		</collision>
	</link>

	<gazebo reference="wam_link_4">
		<material>Gazebo/White</material>
		<selfCollide>true</selfCollide>
	</gazebo>

	<joint name="wam_joint_4" type="revolute">
		<parent link="${parent}"/>
		<child link="wam_link_4"/>
		<origin rpy="-1.57079632679 0 0" xyz="0.045 0.0 0.55"/>
		<axis xyz="0 0 1"/>
		<limit effort="35" lower="-0.9" upper="3.1" velocity="2.0"/>
		<!-- <joint_properties damping="100.0" friction="1000.0" /> -->
		<dynamics damping="0.4" friction="${3.0/7}"/>
	</joint>

	<transmission name="j4_transmission">
		<type>transmission_interface/SimpleTransmission"</type>
		<joint name="wam_joint_4">
			<hardwareInterface>EffortJointInterface</hardwareInterface>
		</joint>
		<actuator name="j4_motor">
			<hardwareInterface>EffortJointInterface</hardwareInterface>
			<mechanicalReduction>1</mechanicalReduction>
		</actuator>
	</transmission>

  </xacro:macro>

</robot>

